(dp1
S'output'
p2
S"<type 'exceptions.AttributeError'> 'Table' object has no attribute 'id'"
p3
sS'layer'
p4
S'C:\\Users\\Miguel\\Documents\\4 periodo\\IBD\\web2py_win\\web2py\\applications\\evento\\controllers/default.py'
p5
sS'code'
p6
S'<code object <module> at 09C25338, file "C:\\Users\\Miguel\\Documents\\4 periodo\\IBD\\web2py_win\\web2py\\applications\\evento\\controllers/default.py", line 8>'
p7
sS'snapshot'
p8
(dp9
sS'traceback'
p10
S'Traceback (most recent call last):\n  File "C:\\Users\\Miguel\\Documents\\4 periodo\\IBD\\web2py_win\\web2py\\gluon\\restricted.py", line 219, in restricted\n    exec(ccode, environment)\n  File "C:\\Users\\Miguel\\Documents\\4 periodo\\IBD\\web2py_win\\web2py\\applications\\evento\\controllers/default.py", line 88, in <module>\n  File "C:\\Users\\Miguel\\Documents\\4 periodo\\IBD\\web2py_win\\web2py\\gluon\\globals.py", line 421, in <lambda>\n    self._caller = lambda f: f()\n  File "C:\\Users\\Miguel\\Documents\\4 periodo\\IBD\\web2py_win\\web2py\\applications\\evento\\controllers/default.py", line 55, in meus_eventos\n    query = db.Evento.id == db.Participacoes.id and session.auth.user.id == db.Participacoes.cli_id\nAttributeError: \'Table\' object has no attribute \'id\'\n'
p11
s.